{
 "cells": [
  {
   "cell_type": "markdown",
   "metadata": {},
   "source": [
    "# 天気"
   ]
  },
  {
   "cell_type": "code",
   "execution_count": 11,
   "metadata": {
    "collapsed": false
   },
   "outputs": [],
   "source": [
    "import tkinter as tk\n",
    "import requests\n",
    "import pprint\n",
    "\n",
    "base = tk.Tk()\n",
    "base.title(\"天気\")\n",
    "city_tuple = (\"札幌\", \"東京\", \"大阪\")\n",
    "city_dic = {\"札幌\":\"016010\", \"東京\":\"130010\", \"大阪\":\"270000\"}\n",
    "check_value ={}\n",
    "\n",
    "for i in city_tuple:\n",
    "    check_value[i] = tk.BooleanVar()\n",
    "    tk.Checkbutton(base, variable=check_value[i], text=i).pack(anchor=tk.W)\n",
    "    \n"
   ]
  },
  {
   "cell_type": "code",
   "execution_count": 12,
   "metadata": {
    "collapsed": false
   },
   "outputs": [],
   "source": [
    "def weather():\n",
    "    for i in check_value:\n",
    "        if check_value[i].get() == True:\n",
    "            #url = (\"http://weather.livedoor.com/forecast/\" \"webservice/json/v1\")\n",
    "            url = (\"http://weather.livedoor.com/forecast/\")\n",
    "            payload = {\"city\":city_dic[i]}\n",
    "            data_1 = requests.get(url,params=payload).json()\n",
    "            pprint.pprint(data_1[\"location\"])\n",
    "            for i in range(3):\n",
    "                print(data_1[\"forecasts\"][i][\"dateLabel\"] + \"の天気は、\" +\n",
    "                data_1[\"forecasts\"][i][\"telop\"])\n",
    "                print()\n",
    "                "
   ]
  },
  {
   "cell_type": "code",
   "execution_count": 13,
   "metadata": {
    "collapsed": false,
    "scrolled": false
   },
   "outputs": [
    {
     "name": "stderr",
     "output_type": "stream",
     "text": [
      "Exception in Tkinter callback\n",
      "Traceback (most recent call last):\n",
      "  File \"C:\\Anaconda3\\lib\\site-packages\\requests\\packages\\urllib3\\connection.py\", line 137, in _new_conn\n",
      "    (self.host, self.port), self.timeout, **extra_kw)\n",
      "  File \"C:\\Anaconda3\\lib\\site-packages\\requests\\packages\\urllib3\\util\\connection.py\", line 67, in create_connection\n",
      "    for res in socket.getaddrinfo(host, port, 0, socket.SOCK_STREAM):\n",
      "  File \"C:\\Anaconda3\\lib\\socket.py\", line 732, in getaddrinfo\n",
      "    for res in _socket.getaddrinfo(host, port, family, type, proto, flags):\n",
      "socket.gaierror: [Errno 11001] getaddrinfo failed\n",
      "\n",
      "During handling of the above exception, another exception occurred:\n",
      "\n",
      "Traceback (most recent call last):\n",
      "  File \"C:\\Anaconda3\\lib\\site-packages\\requests\\packages\\urllib3\\connectionpool.py\", line 559, in urlopen\n",
      "    body=body, headers=headers)\n",
      "  File \"C:\\Anaconda3\\lib\\site-packages\\requests\\packages\\urllib3\\connectionpool.py\", line 353, in _make_request\n",
      "    conn.request(method, url, **httplib_request_kw)\n",
      "  File \"C:\\Anaconda3\\lib\\http\\client.py\", line 1083, in request\n",
      "    self._send_request(method, url, body, headers)\n",
      "  File \"C:\\Anaconda3\\lib\\http\\client.py\", line 1128, in _send_request\n",
      "    self.endheaders(body)\n",
      "  File \"C:\\Anaconda3\\lib\\http\\client.py\", line 1079, in endheaders\n",
      "    self._send_output(message_body)\n",
      "  File \"C:\\Anaconda3\\lib\\http\\client.py\", line 911, in _send_output\n",
      "    self.send(msg)\n",
      "  File \"C:\\Anaconda3\\lib\\http\\client.py\", line 854, in send\n",
      "    self.connect()\n",
      "  File \"C:\\Anaconda3\\lib\\site-packages\\requests\\packages\\urllib3\\connection.py\", line 162, in connect\n",
      "    conn = self._new_conn()\n",
      "  File \"C:\\Anaconda3\\lib\\site-packages\\requests\\packages\\urllib3\\connection.py\", line 146, in _new_conn\n",
      "    self, \"Failed to establish a new connection: %s\" % e)\n",
      "requests.packages.urllib3.exceptions.NewConnectionError: <requests.packages.urllib3.connection.HTTPConnection object at 0x000002C13812ABE0>: Failed to establish a new connection: [Errno 11001] getaddrinfo failed\n",
      "\n",
      "During handling of the above exception, another exception occurred:\n",
      "\n",
      "Traceback (most recent call last):\n",
      "  File \"C:\\Anaconda3\\lib\\site-packages\\requests\\adapters.py\", line 376, in send\n",
      "    timeout=timeout\n",
      "  File \"C:\\Anaconda3\\lib\\site-packages\\requests\\packages\\urllib3\\connectionpool.py\", line 609, in urlopen\n",
      "    _stacktrace=sys.exc_info()[2])\n",
      "  File \"C:\\Anaconda3\\lib\\site-packages\\requests\\packages\\urllib3\\util\\retry.py\", line 273, in increment\n",
      "    raise MaxRetryError(_pool, url, error or ResponseError(cause))\n",
      "requests.packages.urllib3.exceptions.MaxRetryError: HTTPConnectionPool(host='weather.livedoor.com', port=80): Max retries exceeded with url: /forecast/?city=130010 (Caused by NewConnectionError('<requests.packages.urllib3.connection.HTTPConnection object at 0x000002C13812ABE0>: Failed to establish a new connection: [Errno 11001] getaddrinfo failed',))\n",
      "\n",
      "During handling of the above exception, another exception occurred:\n",
      "\n",
      "Traceback (most recent call last):\n",
      "  File \"C:\\Anaconda3\\lib\\tkinter\\__init__.py\", line 1549, in __call__\n",
      "    return self.func(*args)\n",
      "  File \"<ipython-input-12-afaf9edfc70c>\", line 7, in weather\n",
      "    data_1 = requests.get(url,params=payload).json()\n",
      "  File \"C:\\Anaconda3\\lib\\site-packages\\requests\\api.py\", line 67, in get\n",
      "    return request('get', url, params=params, **kwargs)\n",
      "  File \"C:\\Anaconda3\\lib\\site-packages\\requests\\api.py\", line 53, in request\n",
      "    return session.request(method=method, url=url, **kwargs)\n",
      "  File \"C:\\Anaconda3\\lib\\site-packages\\requests\\sessions.py\", line 468, in request\n",
      "    resp = self.send(prep, **send_kwargs)\n",
      "  File \"C:\\Anaconda3\\lib\\site-packages\\requests\\sessions.py\", line 576, in send\n",
      "    r = adapter.send(request, **kwargs)\n",
      "  File \"C:\\Anaconda3\\lib\\site-packages\\requests\\adapters.py\", line 437, in send\n",
      "    raise ConnectionError(e, request=request)\n",
      "requests.exceptions.ConnectionError: HTTPConnectionPool(host='weather.livedoor.com', port=80): Max retries exceeded with url: /forecast/?city=130010 (Caused by NewConnectionError('<requests.packages.urllib3.connection.HTTPConnection object at 0x000002C13812ABE0>: Failed to establish a new connection: [Errno 11001] getaddrinfo failed',))\n",
      "Exception in Tkinter callback\n",
      "Traceback (most recent call last):\n",
      "  File \"C:\\Anaconda3\\lib\\site-packages\\requests\\packages\\urllib3\\connection.py\", line 137, in _new_conn\n",
      "    (self.host, self.port), self.timeout, **extra_kw)\n",
      "  File \"C:\\Anaconda3\\lib\\site-packages\\requests\\packages\\urllib3\\util\\connection.py\", line 67, in create_connection\n",
      "    for res in socket.getaddrinfo(host, port, 0, socket.SOCK_STREAM):\n",
      "  File \"C:\\Anaconda3\\lib\\socket.py\", line 732, in getaddrinfo\n",
      "    for res in _socket.getaddrinfo(host, port, family, type, proto, flags):\n",
      "socket.gaierror: [Errno 11001] getaddrinfo failed\n",
      "\n",
      "During handling of the above exception, another exception occurred:\n",
      "\n",
      "Traceback (most recent call last):\n",
      "  File \"C:\\Anaconda3\\lib\\site-packages\\requests\\packages\\urllib3\\connectionpool.py\", line 559, in urlopen\n",
      "    body=body, headers=headers)\n",
      "  File \"C:\\Anaconda3\\lib\\site-packages\\requests\\packages\\urllib3\\connectionpool.py\", line 353, in _make_request\n",
      "    conn.request(method, url, **httplib_request_kw)\n",
      "  File \"C:\\Anaconda3\\lib\\http\\client.py\", line 1083, in request\n",
      "    self._send_request(method, url, body, headers)\n",
      "  File \"C:\\Anaconda3\\lib\\http\\client.py\", line 1128, in _send_request\n",
      "    self.endheaders(body)\n",
      "  File \"C:\\Anaconda3\\lib\\http\\client.py\", line 1079, in endheaders\n",
      "    self._send_output(message_body)\n",
      "  File \"C:\\Anaconda3\\lib\\http\\client.py\", line 911, in _send_output\n",
      "    self.send(msg)\n",
      "  File \"C:\\Anaconda3\\lib\\http\\client.py\", line 854, in send\n",
      "    self.connect()\n",
      "  File \"C:\\Anaconda3\\lib\\site-packages\\requests\\packages\\urllib3\\connection.py\", line 162, in connect\n",
      "    conn = self._new_conn()\n",
      "  File \"C:\\Anaconda3\\lib\\site-packages\\requests\\packages\\urllib3\\connection.py\", line 146, in _new_conn\n",
      "    self, \"Failed to establish a new connection: %s\" % e)\n",
      "requests.packages.urllib3.exceptions.NewConnectionError: <requests.packages.urllib3.connection.HTTPConnection object at 0x000002C13812A3C8>: Failed to establish a new connection: [Errno 11001] getaddrinfo failed\n",
      "\n",
      "During handling of the above exception, another exception occurred:\n",
      "\n",
      "Traceback (most recent call last):\n",
      "  File \"C:\\Anaconda3\\lib\\site-packages\\requests\\adapters.py\", line 376, in send\n",
      "    timeout=timeout\n",
      "  File \"C:\\Anaconda3\\lib\\site-packages\\requests\\packages\\urllib3\\connectionpool.py\", line 609, in urlopen\n",
      "    _stacktrace=sys.exc_info()[2])\n",
      "  File \"C:\\Anaconda3\\lib\\site-packages\\requests\\packages\\urllib3\\util\\retry.py\", line 273, in increment\n",
      "    raise MaxRetryError(_pool, url, error or ResponseError(cause))\n",
      "requests.packages.urllib3.exceptions.MaxRetryError: HTTPConnectionPool(host='weather.livedoor.com', port=80): Max retries exceeded with url: /forecast/?city=130010 (Caused by NewConnectionError('<requests.packages.urllib3.connection.HTTPConnection object at 0x000002C13812A3C8>: Failed to establish a new connection: [Errno 11001] getaddrinfo failed',))\n",
      "\n",
      "During handling of the above exception, another exception occurred:\n",
      "\n",
      "Traceback (most recent call last):\n",
      "  File \"C:\\Anaconda3\\lib\\tkinter\\__init__.py\", line 1549, in __call__\n",
      "    return self.func(*args)\n",
      "  File \"<ipython-input-12-afaf9edfc70c>\", line 7, in weather\n",
      "    data_1 = requests.get(url,params=payload).json()\n",
      "  File \"C:\\Anaconda3\\lib\\site-packages\\requests\\api.py\", line 67, in get\n",
      "    return request('get', url, params=params, **kwargs)\n",
      "  File \"C:\\Anaconda3\\lib\\site-packages\\requests\\api.py\", line 53, in request\n",
      "    return session.request(method=method, url=url, **kwargs)\n",
      "  File \"C:\\Anaconda3\\lib\\site-packages\\requests\\sessions.py\", line 468, in request\n",
      "    resp = self.send(prep, **send_kwargs)\n",
      "  File \"C:\\Anaconda3\\lib\\site-packages\\requests\\sessions.py\", line 576, in send\n",
      "    r = adapter.send(request, **kwargs)\n",
      "  File \"C:\\Anaconda3\\lib\\site-packages\\requests\\adapters.py\", line 437, in send\n",
      "    raise ConnectionError(e, request=request)\n",
      "requests.exceptions.ConnectionError: HTTPConnectionPool(host='weather.livedoor.com', port=80): Max retries exceeded with url: /forecast/?city=130010 (Caused by NewConnectionError('<requests.packages.urllib3.connection.HTTPConnection object at 0x000002C13812A3C8>: Failed to establish a new connection: [Errno 11001] getaddrinfo failed',))\n",
      "Exception in Tkinter callback\n",
      "Traceback (most recent call last):\n",
      "  File \"C:\\Anaconda3\\lib\\site-packages\\requests\\packages\\urllib3\\connection.py\", line 137, in _new_conn\n",
      "    (self.host, self.port), self.timeout, **extra_kw)\n",
      "  File \"C:\\Anaconda3\\lib\\site-packages\\requests\\packages\\urllib3\\util\\connection.py\", line 67, in create_connection\n",
      "    for res in socket.getaddrinfo(host, port, 0, socket.SOCK_STREAM):\n",
      "  File \"C:\\Anaconda3\\lib\\socket.py\", line 732, in getaddrinfo\n",
      "    for res in _socket.getaddrinfo(host, port, family, type, proto, flags):\n",
      "socket.gaierror: [Errno 11001] getaddrinfo failed\n",
      "\n",
      "During handling of the above exception, another exception occurred:\n",
      "\n",
      "Traceback (most recent call last):\n",
      "  File \"C:\\Anaconda3\\lib\\site-packages\\requests\\packages\\urllib3\\connectionpool.py\", line 559, in urlopen\n",
      "    body=body, headers=headers)\n",
      "  File \"C:\\Anaconda3\\lib\\site-packages\\requests\\packages\\urllib3\\connectionpool.py\", line 353, in _make_request\n",
      "    conn.request(method, url, **httplib_request_kw)\n",
      "  File \"C:\\Anaconda3\\lib\\http\\client.py\", line 1083, in request\n",
      "    self._send_request(method, url, body, headers)\n",
      "  File \"C:\\Anaconda3\\lib\\http\\client.py\", line 1128, in _send_request\n",
      "    self.endheaders(body)\n",
      "  File \"C:\\Anaconda3\\lib\\http\\client.py\", line 1079, in endheaders\n",
      "    self._send_output(message_body)\n",
      "  File \"C:\\Anaconda3\\lib\\http\\client.py\", line 911, in _send_output\n",
      "    self.send(msg)\n",
      "  File \"C:\\Anaconda3\\lib\\http\\client.py\", line 854, in send\n",
      "    self.connect()\n",
      "  File \"C:\\Anaconda3\\lib\\site-packages\\requests\\packages\\urllib3\\connection.py\", line 162, in connect\n",
      "    conn = self._new_conn()\n",
      "  File \"C:\\Anaconda3\\lib\\site-packages\\requests\\packages\\urllib3\\connection.py\", line 146, in _new_conn\n",
      "    self, \"Failed to establish a new connection: %s\" % e)\n",
      "requests.packages.urllib3.exceptions.NewConnectionError: <requests.packages.urllib3.connection.HTTPConnection object at 0x000002C13812A400>: Failed to establish a new connection: [Errno 11001] getaddrinfo failed\n",
      "\n",
      "During handling of the above exception, another exception occurred:\n",
      "\n",
      "Traceback (most recent call last):\n",
      "  File \"C:\\Anaconda3\\lib\\site-packages\\requests\\adapters.py\", line 376, in send\n",
      "    timeout=timeout\n",
      "  File \"C:\\Anaconda3\\lib\\site-packages\\requests\\packages\\urllib3\\connectionpool.py\", line 609, in urlopen\n",
      "    _stacktrace=sys.exc_info()[2])\n",
      "  File \"C:\\Anaconda3\\lib\\site-packages\\requests\\packages\\urllib3\\util\\retry.py\", line 273, in increment\n",
      "    raise MaxRetryError(_pool, url, error or ResponseError(cause))\n",
      "requests.packages.urllib3.exceptions.MaxRetryError: HTTPConnectionPool(host='weather.livedoor.com', port=80): Max retries exceeded with url: /forecast/?city=130010 (Caused by NewConnectionError('<requests.packages.urllib3.connection.HTTPConnection object at 0x000002C13812A400>: Failed to establish a new connection: [Errno 11001] getaddrinfo failed',))\n",
      "\n",
      "During handling of the above exception, another exception occurred:\n",
      "\n",
      "Traceback (most recent call last):\n",
      "  File \"C:\\Anaconda3\\lib\\tkinter\\__init__.py\", line 1549, in __call__\n",
      "    return self.func(*args)\n",
      "  File \"<ipython-input-12-afaf9edfc70c>\", line 7, in weather\n",
      "    data_1 = requests.get(url,params=payload).json()\n",
      "  File \"C:\\Anaconda3\\lib\\site-packages\\requests\\api.py\", line 67, in get\n",
      "    return request('get', url, params=params, **kwargs)\n",
      "  File \"C:\\Anaconda3\\lib\\site-packages\\requests\\api.py\", line 53, in request\n",
      "    return session.request(method=method, url=url, **kwargs)\n",
      "  File \"C:\\Anaconda3\\lib\\site-packages\\requests\\sessions.py\", line 468, in request\n",
      "    resp = self.send(prep, **send_kwargs)\n",
      "  File \"C:\\Anaconda3\\lib\\site-packages\\requests\\sessions.py\", line 576, in send\n",
      "    r = adapter.send(request, **kwargs)\n",
      "  File \"C:\\Anaconda3\\lib\\site-packages\\requests\\adapters.py\", line 437, in send\n",
      "    raise ConnectionError(e, request=request)\n",
      "requests.exceptions.ConnectionError: HTTPConnectionPool(host='weather.livedoor.com', port=80): Max retries exceeded with url: /forecast/?city=130010 (Caused by NewConnectionError('<requests.packages.urllib3.connection.HTTPConnection object at 0x000002C13812A400>: Failed to establish a new connection: [Errno 11001] getaddrinfo failed',))\n",
      "Exception in Tkinter callback\n",
      "Traceback (most recent call last):\n",
      "  File \"C:\\Anaconda3\\lib\\site-packages\\requests\\packages\\urllib3\\connection.py\", line 137, in _new_conn\n",
      "    (self.host, self.port), self.timeout, **extra_kw)\n",
      "  File \"C:\\Anaconda3\\lib\\site-packages\\requests\\packages\\urllib3\\util\\connection.py\", line 67, in create_connection\n",
      "    for res in socket.getaddrinfo(host, port, 0, socket.SOCK_STREAM):\n",
      "  File \"C:\\Anaconda3\\lib\\socket.py\", line 732, in getaddrinfo\n",
      "    for res in _socket.getaddrinfo(host, port, family, type, proto, flags):\n",
      "socket.gaierror: [Errno 11001] getaddrinfo failed\n",
      "\n",
      "During handling of the above exception, another exception occurred:\n",
      "\n",
      "Traceback (most recent call last):\n",
      "  File \"C:\\Anaconda3\\lib\\site-packages\\requests\\packages\\urllib3\\connectionpool.py\", line 559, in urlopen\n",
      "    body=body, headers=headers)\n",
      "  File \"C:\\Anaconda3\\lib\\site-packages\\requests\\packages\\urllib3\\connectionpool.py\", line 353, in _make_request\n",
      "    conn.request(method, url, **httplib_request_kw)\n",
      "  File \"C:\\Anaconda3\\lib\\http\\client.py\", line 1083, in request\n",
      "    self._send_request(method, url, body, headers)\n",
      "  File \"C:\\Anaconda3\\lib\\http\\client.py\", line 1128, in _send_request\n",
      "    self.endheaders(body)\n",
      "  File \"C:\\Anaconda3\\lib\\http\\client.py\", line 1079, in endheaders\n",
      "    self._send_output(message_body)\n",
      "  File \"C:\\Anaconda3\\lib\\http\\client.py\", line 911, in _send_output\n",
      "    self.send(msg)\n",
      "  File \"C:\\Anaconda3\\lib\\http\\client.py\", line 854, in send\n",
      "    self.connect()\n",
      "  File \"C:\\Anaconda3\\lib\\site-packages\\requests\\packages\\urllib3\\connection.py\", line 162, in connect\n",
      "    conn = self._new_conn()\n",
      "  File \"C:\\Anaconda3\\lib\\site-packages\\requests\\packages\\urllib3\\connection.py\", line 146, in _new_conn\n",
      "    self, \"Failed to establish a new connection: %s\" % e)\n",
      "requests.packages.urllib3.exceptions.NewConnectionError: <requests.packages.urllib3.connection.HTTPConnection object at 0x000002C13812A7F0>: Failed to establish a new connection: [Errno 11001] getaddrinfo failed\n",
      "\n",
      "During handling of the above exception, another exception occurred:\n",
      "\n",
      "Traceback (most recent call last):\n",
      "  File \"C:\\Anaconda3\\lib\\site-packages\\requests\\adapters.py\", line 376, in send\n",
      "    timeout=timeout\n",
      "  File \"C:\\Anaconda3\\lib\\site-packages\\requests\\packages\\urllib3\\connectionpool.py\", line 609, in urlopen\n",
      "    _stacktrace=sys.exc_info()[2])\n",
      "  File \"C:\\Anaconda3\\lib\\site-packages\\requests\\packages\\urllib3\\util\\retry.py\", line 273, in increment\n",
      "    raise MaxRetryError(_pool, url, error or ResponseError(cause))\n",
      "requests.packages.urllib3.exceptions.MaxRetryError: HTTPConnectionPool(host='weather.livedoor.com', port=80): Max retries exceeded with url: /forecast/?city=130010 (Caused by NewConnectionError('<requests.packages.urllib3.connection.HTTPConnection object at 0x000002C13812A7F0>: Failed to establish a new connection: [Errno 11001] getaddrinfo failed',))\n",
      "\n",
      "During handling of the above exception, another exception occurred:\n",
      "\n",
      "Traceback (most recent call last):\n",
      "  File \"C:\\Anaconda3\\lib\\tkinter\\__init__.py\", line 1549, in __call__\n",
      "    return self.func(*args)\n",
      "  File \"<ipython-input-12-afaf9edfc70c>\", line 7, in weather\n",
      "    data_1 = requests.get(url,params=payload).json()\n",
      "  File \"C:\\Anaconda3\\lib\\site-packages\\requests\\api.py\", line 67, in get\n",
      "    return request('get', url, params=params, **kwargs)\n",
      "  File \"C:\\Anaconda3\\lib\\site-packages\\requests\\api.py\", line 53, in request\n",
      "    return session.request(method=method, url=url, **kwargs)\n",
      "  File \"C:\\Anaconda3\\lib\\site-packages\\requests\\sessions.py\", line 468, in request\n",
      "    resp = self.send(prep, **send_kwargs)\n",
      "  File \"C:\\Anaconda3\\lib\\site-packages\\requests\\sessions.py\", line 576, in send\n",
      "    r = adapter.send(request, **kwargs)\n",
      "  File \"C:\\Anaconda3\\lib\\site-packages\\requests\\adapters.py\", line 437, in send\n",
      "    raise ConnectionError(e, request=request)\n",
      "requests.exceptions.ConnectionError: HTTPConnectionPool(host='weather.livedoor.com', port=80): Max retries exceeded with url: /forecast/?city=130010 (Caused by NewConnectionError('<requests.packages.urllib3.connection.HTTPConnection object at 0x000002C13812A7F0>: Failed to establish a new connection: [Errno 11001] getaddrinfo failed',))\n",
      "Exception in Tkinter callback\n",
      "Traceback (most recent call last):\n",
      "  File \"C:\\Anaconda3\\lib\\site-packages\\requests\\packages\\urllib3\\connection.py\", line 137, in _new_conn\n",
      "    (self.host, self.port), self.timeout, **extra_kw)\n",
      "  File \"C:\\Anaconda3\\lib\\site-packages\\requests\\packages\\urllib3\\util\\connection.py\", line 67, in create_connection\n",
      "    for res in socket.getaddrinfo(host, port, 0, socket.SOCK_STREAM):\n",
      "  File \"C:\\Anaconda3\\lib\\socket.py\", line 732, in getaddrinfo\n",
      "    for res in _socket.getaddrinfo(host, port, family, type, proto, flags):\n",
      "socket.gaierror: [Errno 11001] getaddrinfo failed\n",
      "\n",
      "During handling of the above exception, another exception occurred:\n",
      "\n",
      "Traceback (most recent call last):\n",
      "  File \"C:\\Anaconda3\\lib\\site-packages\\requests\\packages\\urllib3\\connectionpool.py\", line 559, in urlopen\n",
      "    body=body, headers=headers)\n",
      "  File \"C:\\Anaconda3\\lib\\site-packages\\requests\\packages\\urllib3\\connectionpool.py\", line 353, in _make_request\n",
      "    conn.request(method, url, **httplib_request_kw)\n",
      "  File \"C:\\Anaconda3\\lib\\http\\client.py\", line 1083, in request\n",
      "    self._send_request(method, url, body, headers)\n",
      "  File \"C:\\Anaconda3\\lib\\http\\client.py\", line 1128, in _send_request\n",
      "    self.endheaders(body)\n",
      "  File \"C:\\Anaconda3\\lib\\http\\client.py\", line 1079, in endheaders\n",
      "    self._send_output(message_body)\n",
      "  File \"C:\\Anaconda3\\lib\\http\\client.py\", line 911, in _send_output\n",
      "    self.send(msg)\n",
      "  File \"C:\\Anaconda3\\lib\\http\\client.py\", line 854, in send\n",
      "    self.connect()\n",
      "  File \"C:\\Anaconda3\\lib\\site-packages\\requests\\packages\\urllib3\\connection.py\", line 162, in connect\n",
      "    conn = self._new_conn()\n",
      "  File \"C:\\Anaconda3\\lib\\site-packages\\requests\\packages\\urllib3\\connection.py\", line 146, in _new_conn\n",
      "    self, \"Failed to establish a new connection: %s\" % e)\n",
      "requests.packages.urllib3.exceptions.NewConnectionError: <requests.packages.urllib3.connection.HTTPConnection object at 0x000002C13812A518>: Failed to establish a new connection: [Errno 11001] getaddrinfo failed\n",
      "\n",
      "During handling of the above exception, another exception occurred:\n",
      "\n",
      "Traceback (most recent call last):\n",
      "  File \"C:\\Anaconda3\\lib\\site-packages\\requests\\adapters.py\", line 376, in send\n",
      "    timeout=timeout\n",
      "  File \"C:\\Anaconda3\\lib\\site-packages\\requests\\packages\\urllib3\\connectionpool.py\", line 609, in urlopen\n",
      "    _stacktrace=sys.exc_info()[2])\n",
      "  File \"C:\\Anaconda3\\lib\\site-packages\\requests\\packages\\urllib3\\util\\retry.py\", line 273, in increment\n",
      "    raise MaxRetryError(_pool, url, error or ResponseError(cause))\n",
      "requests.packages.urllib3.exceptions.MaxRetryError: HTTPConnectionPool(host='weather.livedoor.com', port=80): Max retries exceeded with url: /forecast/?city=130010 (Caused by NewConnectionError('<requests.packages.urllib3.connection.HTTPConnection object at 0x000002C13812A518>: Failed to establish a new connection: [Errno 11001] getaddrinfo failed',))\n",
      "\n",
      "During handling of the above exception, another exception occurred:\n",
      "\n",
      "Traceback (most recent call last):\n",
      "  File \"C:\\Anaconda3\\lib\\tkinter\\__init__.py\", line 1549, in __call__\n",
      "    return self.func(*args)\n",
      "  File \"<ipython-input-12-afaf9edfc70c>\", line 7, in weather\n",
      "    data_1 = requests.get(url,params=payload).json()\n",
      "  File \"C:\\Anaconda3\\lib\\site-packages\\requests\\api.py\", line 67, in get\n",
      "    return request('get', url, params=params, **kwargs)\n",
      "  File \"C:\\Anaconda3\\lib\\site-packages\\requests\\api.py\", line 53, in request\n",
      "    return session.request(method=method, url=url, **kwargs)\n",
      "  File \"C:\\Anaconda3\\lib\\site-packages\\requests\\sessions.py\", line 468, in request\n",
      "    resp = self.send(prep, **send_kwargs)\n",
      "  File \"C:\\Anaconda3\\lib\\site-packages\\requests\\sessions.py\", line 576, in send\n",
      "    r = adapter.send(request, **kwargs)\n",
      "  File \"C:\\Anaconda3\\lib\\site-packages\\requests\\adapters.py\", line 437, in send\n",
      "    raise ConnectionError(e, request=request)\n",
      "requests.exceptions.ConnectionError: HTTPConnectionPool(host='weather.livedoor.com', port=80): Max retries exceeded with url: /forecast/?city=130010 (Caused by NewConnectionError('<requests.packages.urllib3.connection.HTTPConnection object at 0x000002C13812A518>: Failed to establish a new connection: [Errno 11001] getaddrinfo failed',))\n",
      "Exception in Tkinter callback\n",
      "Traceback (most recent call last):\n",
      "  File \"C:\\Anaconda3\\lib\\site-packages\\requests\\packages\\urllib3\\connection.py\", line 137, in _new_conn\n",
      "    (self.host, self.port), self.timeout, **extra_kw)\n",
      "  File \"C:\\Anaconda3\\lib\\site-packages\\requests\\packages\\urllib3\\util\\connection.py\", line 67, in create_connection\n",
      "    for res in socket.getaddrinfo(host, port, 0, socket.SOCK_STREAM):\n",
      "  File \"C:\\Anaconda3\\lib\\socket.py\", line 732, in getaddrinfo\n",
      "    for res in _socket.getaddrinfo(host, port, family, type, proto, flags):\n",
      "socket.gaierror: [Errno 11001] getaddrinfo failed\n",
      "\n",
      "During handling of the above exception, another exception occurred:\n",
      "\n",
      "Traceback (most recent call last):\n",
      "  File \"C:\\Anaconda3\\lib\\site-packages\\requests\\packages\\urllib3\\connectionpool.py\", line 559, in urlopen\n",
      "    body=body, headers=headers)\n",
      "  File \"C:\\Anaconda3\\lib\\site-packages\\requests\\packages\\urllib3\\connectionpool.py\", line 353, in _make_request\n",
      "    conn.request(method, url, **httplib_request_kw)\n",
      "  File \"C:\\Anaconda3\\lib\\http\\client.py\", line 1083, in request\n",
      "    self._send_request(method, url, body, headers)\n",
      "  File \"C:\\Anaconda3\\lib\\http\\client.py\", line 1128, in _send_request\n",
      "    self.endheaders(body)\n",
      "  File \"C:\\Anaconda3\\lib\\http\\client.py\", line 1079, in endheaders\n",
      "    self._send_output(message_body)\n",
      "  File \"C:\\Anaconda3\\lib\\http\\client.py\", line 911, in _send_output\n",
      "    self.send(msg)\n",
      "  File \"C:\\Anaconda3\\lib\\http\\client.py\", line 854, in send\n",
      "    self.connect()\n",
      "  File \"C:\\Anaconda3\\lib\\site-packages\\requests\\packages\\urllib3\\connection.py\", line 162, in connect\n",
      "    conn = self._new_conn()\n",
      "  File \"C:\\Anaconda3\\lib\\site-packages\\requests\\packages\\urllib3\\connection.py\", line 146, in _new_conn\n",
      "    self, \"Failed to establish a new connection: %s\" % e)\n",
      "requests.packages.urllib3.exceptions.NewConnectionError: <requests.packages.urllib3.connection.HTTPConnection object at 0x000002C13812AA58>: Failed to establish a new connection: [Errno 11001] getaddrinfo failed\n",
      "\n",
      "During handling of the above exception, another exception occurred:\n",
      "\n",
      "Traceback (most recent call last):\n",
      "  File \"C:\\Anaconda3\\lib\\site-packages\\requests\\adapters.py\", line 376, in send\n",
      "    timeout=timeout\n",
      "  File \"C:\\Anaconda3\\lib\\site-packages\\requests\\packages\\urllib3\\connectionpool.py\", line 609, in urlopen\n",
      "    _stacktrace=sys.exc_info()[2])\n",
      "  File \"C:\\Anaconda3\\lib\\site-packages\\requests\\packages\\urllib3\\util\\retry.py\", line 273, in increment\n",
      "    raise MaxRetryError(_pool, url, error or ResponseError(cause))\n",
      "requests.packages.urllib3.exceptions.MaxRetryError: HTTPConnectionPool(host='weather.livedoor.com', port=80): Max retries exceeded with url: /forecast/?city=130010 (Caused by NewConnectionError('<requests.packages.urllib3.connection.HTTPConnection object at 0x000002C13812AA58>: Failed to establish a new connection: [Errno 11001] getaddrinfo failed',))\n",
      "\n",
      "During handling of the above exception, another exception occurred:\n",
      "\n",
      "Traceback (most recent call last):\n",
      "  File \"C:\\Anaconda3\\lib\\tkinter\\__init__.py\", line 1549, in __call__\n",
      "    return self.func(*args)\n",
      "  File \"<ipython-input-12-afaf9edfc70c>\", line 7, in weather\n",
      "    data_1 = requests.get(url,params=payload).json()\n",
      "  File \"C:\\Anaconda3\\lib\\site-packages\\requests\\api.py\", line 67, in get\n",
      "    return request('get', url, params=params, **kwargs)\n",
      "  File \"C:\\Anaconda3\\lib\\site-packages\\requests\\api.py\", line 53, in request\n",
      "    return session.request(method=method, url=url, **kwargs)\n",
      "  File \"C:\\Anaconda3\\lib\\site-packages\\requests\\sessions.py\", line 468, in request\n",
      "    resp = self.send(prep, **send_kwargs)\n",
      "  File \"C:\\Anaconda3\\lib\\site-packages\\requests\\sessions.py\", line 576, in send\n",
      "    r = adapter.send(request, **kwargs)\n",
      "  File \"C:\\Anaconda3\\lib\\site-packages\\requests\\adapters.py\", line 437, in send\n",
      "    raise ConnectionError(e, request=request)\n",
      "requests.exceptions.ConnectionError: HTTPConnectionPool(host='weather.livedoor.com', port=80): Max retries exceeded with url: /forecast/?city=130010 (Caused by NewConnectionError('<requests.packages.urllib3.connection.HTTPConnection object at 0x000002C13812AA58>: Failed to establish a new connection: [Errno 11001] getaddrinfo failed',))\n",
      "Exception in Tkinter callback\n",
      "Traceback (most recent call last):\n",
      "  File \"C:\\Anaconda3\\lib\\site-packages\\requests\\packages\\urllib3\\connection.py\", line 137, in _new_conn\n",
      "    (self.host, self.port), self.timeout, **extra_kw)\n",
      "  File \"C:\\Anaconda3\\lib\\site-packages\\requests\\packages\\urllib3\\util\\connection.py\", line 67, in create_connection\n",
      "    for res in socket.getaddrinfo(host, port, 0, socket.SOCK_STREAM):\n",
      "  File \"C:\\Anaconda3\\lib\\socket.py\", line 732, in getaddrinfo\n",
      "    for res in _socket.getaddrinfo(host, port, family, type, proto, flags):\n",
      "socket.gaierror: [Errno 11001] getaddrinfo failed\n",
      "\n",
      "During handling of the above exception, another exception occurred:\n",
      "\n",
      "Traceback (most recent call last):\n",
      "  File \"C:\\Anaconda3\\lib\\site-packages\\requests\\packages\\urllib3\\connectionpool.py\", line 559, in urlopen\n",
      "    body=body, headers=headers)\n",
      "  File \"C:\\Anaconda3\\lib\\site-packages\\requests\\packages\\urllib3\\connectionpool.py\", line 353, in _make_request\n",
      "    conn.request(method, url, **httplib_request_kw)\n",
      "  File \"C:\\Anaconda3\\lib\\http\\client.py\", line 1083, in request\n",
      "    self._send_request(method, url, body, headers)\n",
      "  File \"C:\\Anaconda3\\lib\\http\\client.py\", line 1128, in _send_request\n",
      "    self.endheaders(body)\n",
      "  File \"C:\\Anaconda3\\lib\\http\\client.py\", line 1079, in endheaders\n",
      "    self._send_output(message_body)\n",
      "  File \"C:\\Anaconda3\\lib\\http\\client.py\", line 911, in _send_output\n",
      "    self.send(msg)\n",
      "  File \"C:\\Anaconda3\\lib\\http\\client.py\", line 854, in send\n",
      "    self.connect()\n",
      "  File \"C:\\Anaconda3\\lib\\site-packages\\requests\\packages\\urllib3\\connection.py\", line 162, in connect\n",
      "    conn = self._new_conn()\n",
      "  File \"C:\\Anaconda3\\lib\\site-packages\\requests\\packages\\urllib3\\connection.py\", line 146, in _new_conn\n",
      "    self, \"Failed to establish a new connection: %s\" % e)\n",
      "requests.packages.urllib3.exceptions.NewConnectionError: <requests.packages.urllib3.connection.HTTPConnection object at 0x000002C13812A4A8>: Failed to establish a new connection: [Errno 11001] getaddrinfo failed\n",
      "\n",
      "During handling of the above exception, another exception occurred:\n",
      "\n",
      "Traceback (most recent call last):\n",
      "  File \"C:\\Anaconda3\\lib\\site-packages\\requests\\adapters.py\", line 376, in send\n",
      "    timeout=timeout\n",
      "  File \"C:\\Anaconda3\\lib\\site-packages\\requests\\packages\\urllib3\\connectionpool.py\", line 609, in urlopen\n",
      "    _stacktrace=sys.exc_info()[2])\n",
      "  File \"C:\\Anaconda3\\lib\\site-packages\\requests\\packages\\urllib3\\util\\retry.py\", line 273, in increment\n",
      "    raise MaxRetryError(_pool, url, error or ResponseError(cause))\n",
      "requests.packages.urllib3.exceptions.MaxRetryError: HTTPConnectionPool(host='weather.livedoor.com', port=80): Max retries exceeded with url: /forecast/?city=016010 (Caused by NewConnectionError('<requests.packages.urllib3.connection.HTTPConnection object at 0x000002C13812A4A8>: Failed to establish a new connection: [Errno 11001] getaddrinfo failed',))\n",
      "\n",
      "During handling of the above exception, another exception occurred:\n",
      "\n",
      "Traceback (most recent call last):\n",
      "  File \"C:\\Anaconda3\\lib\\tkinter\\__init__.py\", line 1549, in __call__\n",
      "    return self.func(*args)\n",
      "  File \"<ipython-input-12-afaf9edfc70c>\", line 7, in weather\n",
      "    data_1 = requests.get(url,params=payload).json()\n",
      "  File \"C:\\Anaconda3\\lib\\site-packages\\requests\\api.py\", line 67, in get\n",
      "    return request('get', url, params=params, **kwargs)\n",
      "  File \"C:\\Anaconda3\\lib\\site-packages\\requests\\api.py\", line 53, in request\n",
      "    return session.request(method=method, url=url, **kwargs)\n",
      "  File \"C:\\Anaconda3\\lib\\site-packages\\requests\\sessions.py\", line 468, in request\n",
      "    resp = self.send(prep, **send_kwargs)\n",
      "  File \"C:\\Anaconda3\\lib\\site-packages\\requests\\sessions.py\", line 576, in send\n",
      "    r = adapter.send(request, **kwargs)\n",
      "  File \"C:\\Anaconda3\\lib\\site-packages\\requests\\adapters.py\", line 437, in send\n",
      "    raise ConnectionError(e, request=request)\n",
      "requests.exceptions.ConnectionError: HTTPConnectionPool(host='weather.livedoor.com', port=80): Max retries exceeded with url: /forecast/?city=016010 (Caused by NewConnectionError('<requests.packages.urllib3.connection.HTTPConnection object at 0x000002C13812A4A8>: Failed to establish a new connection: [Errno 11001] getaddrinfo failed',))\n"
     ]
    }
   ],
   "source": [
    "tk.Button(base, text=\"天気予報\", command=weather).pack()\n",
    "base.mainloop()"
   ]
  },
  {
   "cell_type": "code",
   "execution_count": null,
   "metadata": {
    "collapsed": true
   },
   "outputs": [],
   "source": []
  }
 ],
 "metadata": {
  "kernelspec": {
   "display_name": "Python 3",
   "language": "python",
   "name": "python3"
  },
  "language_info": {
   "codemirror_mode": {
    "name": "ipython",
    "version": 3
   },
   "file_extension": ".py",
   "mimetype": "text/x-python",
   "name": "python",
   "nbconvert_exporter": "python",
   "pygments_lexer": "ipython3",
   "version": "3.5.1"
  }
 },
 "nbformat": 4,
 "nbformat_minor": 0
}
